<sdf version='1.4'>
  <world name='default'>
    <scene>
      <ambient>0.5 0.5 0.5 1</ambient>
      <background>0.5 0.5 0.5 1</background>
      <shadows>0</shadows>
    </scene>
    <physics type='ode'>
      <gravity>0 0 -9.81</gravity>
      <ode>
        <solver>
          <type>quick</type>
          <iters>10</iters>
          <sor>1.3</sor>
        </solver>
        <constraints>
          <cfm>0</cfm>
          <erp>0.2</erp>
          <contact_max_correcting_vel>10</contact_max_correcting_vel>
          <contact_surface_layer>0.001</contact_surface_layer>
        </constraints>
      </ode>
      <max_step_size>0.001</max_step_size>
      <real_time_factor>1</real_time_factor>
      <real_time_update_rate>1000</real_time_update_rate>
    </physics>
    <light name='directional_light_1' type='directional'>
      <pose>0 20 20 0.1 0.1 0</pose>
      <diffuse>1 1 1 1</diffuse>
      <specular>1 1 1 1</specular>
      <attenuation>
        <range>300</range>
      </attenuation>
      <direction>0.1 0.1 -1</direction>
      <cast_shadows>0</cast_shadows>
    </light>
    <model name='unit_box_yellow'>
      <pose>3 2 0 0 -0 0</pose>
      <link name='link'>
        <inertial>
          <mass>1</mass>
          <inertia>
            <ixx>1</ixx>
            <ixy>0</ixy>
            <ixz>0</ixz>
            <iyy>1</iyy>
            <iyz>0</iyz>
            <izz>1</izz>
          </inertia>
        </inertial>
        <collision name='collision'>
          <geometry>
            <box>
              <size>1 1 0.01</size>
            </box>
          </geometry>
          <max_contacts>10</max_contacts>
          <surface>
            <bounce/>
            <friction>
              <ode/>
            </friction>
            <contact>
              <ode/>
            </contact>
          </surface>
        </collision>
        <visual name='visual'>
          <geometry>
            <box>
              <size>1 1 0.01</size>
            </box>
          </geometry>
          <material>
            <script>
              <uri>file://Media/materials/scripts/tags.material</uri>
              <name>Tags/Tag36_11_00006</name>
            </script>
          </material>
        </visual>
        <velocity_decay>
          <linear>0</linear>
          <angular>0</angular>
        </velocity_decay>
        <self_collide>0</self_collide>
        <kinematic>0</kinematic>
        <gravity>0</gravity>
      </link>
      <static>0</static>
    </model>
    <spherical_coordinates>
      <surface_model>EARTH_WGS84</surface_model>
      <latitude_deg>0</latitude_deg>
      <longitude_deg>0</longitude_deg>
      <elevation>0</elevation>
      <heading_deg>0</heading_deg>
    </spherical_coordinates>
    <model name='hku_m100'>
      <link name='base_link'>
        <pose>0 0 0 0 -0 0</pose>
        <inertial>
          <pose>0 0 0 0 -0 0</pose>
          <mass>1.477</mass>
          <inertia>
            <ixx>0.01152</ixx>
            <ixy>0</ixy>
            <ixz>0</ixz>
            <iyy>0.01152</iyy>
            <iyz>0</iyz>
            <izz>0.0218</izz>
          </inertia>
        </inertial>
        <collision name='base_link_collision'>
          <pose>0 0 0 0 -0 0</pose>
          <geometry>
            <mesh>
              <scale>1 1 1</scale>
              <uri>/home/caochao/catkin_ws/src/hku_m100_description/meshes/hku_m100/hku_m100.stl</uri>
            </mesh>
          </geometry>
          <max_contacts>10</max_contacts>
          <surface>
            <bounce/>
            <friction>
              <ode/>
            </friction>
            <contact>
              <ode/>
            </contact>
          </surface>
        </collision>
        <visual name='base_link_visual'>
          <pose>0 0 0 0 -0 0</pose>
          <geometry>
            <mesh>
              <scale>1 1 1</scale>
              <uri>/home/caochao/catkin_ws/src/hku_m100_description/meshes/hku_m100/hku_m100.dae</uri>
            </mesh>
          </geometry>
        </visual>
        <velocity_decay>
          <linear>0</linear>
          <angular>0</angular>
        </velocity_decay>
        <self_collide>0</self_collide>
        <kinematic>0</kinematic>
        <gravity>1</gravity>
      </link>
      <link name='camera_link'>
        <pose>0.1 0 -0.04 0 -0 0</pose>
        <inertial>
          <pose>0 0 0 0 -0 0</pose>
          <mass>0.001</mass>
          <inertia>
            <ixx>0.0001</ixx>
            <ixy>0</ixy>
            <ixz>0</ixz>
            <iyy>0.0001</iyy>
            <iyz>0</iyz>
            <izz>0.0001</izz>
          </inertia>
        </inertial>
        <collision name='camera_link_collision'>
          <pose>0 0 0 0 -0 0</pose>
          <geometry>
            <mesh>
              <scale>1 1 1</scale>
              <uri>/home/caochao/catkin_ws/src/hku_m100_description/meshes/hku_m100/gimbal.stl</uri>
            </mesh>
          </geometry>
          <surface>
            <contact>
              <ode/>
            </contact>
            <friction>
              <ode/>
            </friction>
            <bounce/>
          </surface>
          <max_contacts>10</max_contacts>
        </collision>
        <visual name='camera_link_visual'>
          <pose>0 0 0 0 -0 0</pose>
          <geometry>
            <mesh>
              <scale>1 1 1</scale>
              <uri>/home/caochao/catkin_ws/src/hku_m100_description/meshes/hku_m100/gimbal.dae</uri>
            </mesh>
          </geometry>
        </visual>
        <gravity>1</gravity>
        <velocity_decay>
          <linear>0</linear>
          <angular>0</angular>
        </velocity_decay>
        <self_collide>0</self_collide>
        <sensor name='camera_camera_sensor' type='camera'>
          <update_rate>10</update_rate>
          <camera name='__default__'>
            <pose>0.027 0 -0.027 0 1.57 0</pose>
            <horizontal_fov>1.5708</horizontal_fov>
            <image>
              <format>R8G8B8</format>
              <width>320</width>
              <height>240</height>
            </image>
            <clip>
              <near>0.01</near>
              <far>100</far>
            </clip>
          </camera>
          <plugin name='camera_controller' filename='libgazebo_ros_camera.so'>
            <cameraName>camera</cameraName>
            <alwaysOn>true</alwaysOn>
            <updateRate>10</updateRate>
            <imageTopicName>/dji_sdk/image_raw</imageTopicName>
            <cameraInfoTopicName>/dji_sdk/camera_info</cameraInfoTopicName>
            <frameName>camera_optical_frame</frameName>
            <robotNamespace>/</robotNamespace>
          </plugin>
        </sensor>
        <kinematic>0</kinematic>
      </link>
      <joint name='camera_joint' type='revolute'>
        <child>camera_link</child>
        <parent>base_link</parent>
        <axis>
          <xyz>1 0 0</xyz>
          <limit>
            <lower>-1e+16</lower>
            <upper>1e+16</upper>
          </limit>
          <dynamics/>
        </axis>
      </joint>
      <pose>0 0 0.3 0 -0 0</pose>
      <static>0</static>
    </model>
    <model name='ground_plane'>
      <static>1</static>
      <link name='link'>
        <collision name='collision'>
          <geometry>
            <plane>
              <normal>0 0 1</normal>
              <size>100 100</size>
            </plane>
          </geometry>
          <surface>
            <friction>
              <ode>
                <mu>100</mu>
                <mu2>50</mu2>
              </ode>
            </friction>
            <bounce/>
            <contact>
              <ode/>
            </contact>
          </surface>
          <max_contacts>10</max_contacts>
        </collision>
        <visual name='visual'>
          <cast_shadows>0</cast_shadows>
          <geometry>
            <plane>
              <normal>0 0 1</normal>
              <size>100 100</size>
            </plane>
          </geometry>
          <material>
            <script>
              <uri>file://media/materials/scripts/gazebo.material</uri>
              <name>Gazebo/Grey</name>
            </script>
          </material>
        </visual>
        <velocity_decay>
          <linear>0</linear>
          <angular>0</angular>
        </velocity_decay>
        <self_collide>0</self_collide>
        <kinematic>0</kinematic>
        <gravity>1</gravity>
      </link>
      <pose>1 -1.55027 0 0 -0 0</pose>
    </model>
    <model name='polaris_ranger_xp900'>
      <static>0</static>
      <link name='chassis'>
        <inertial>
          <mass>720</mass>
          <inertia>
            <ixx>140</ixx>
            <ixy>0</ixy>
            <iyy>550</iyy>
            <ixz>0</ixz>
            <iyz>0</iyz>
            <izz>550</izz>
          </inertia>
          <pose>0.1 0 0.4 0 -0 0</pose>
        </inertial>
        <visual name='visual'>
          <pose>0 0 0 0 0 -1.5708</pose>
          <geometry>
            <mesh>
              <uri>model://polaris_ranger_xp900/meshes/polaris.dae</uri>
              <submesh>
                <name>Body</name>
                <center>0</center>
              </submesh>
            </mesh>
          </geometry>
          <material>
            <script>
              <uri>model://polaris_ranger_xp900/materials/scripts</uri>
              <uri>model://polaris_ranger_xp900/materials/textures</uri>
              <name>PolarisXP900/Diffuse</name>
            </script>
          </material>
        </visual>
        <collision name='chassis_bottom'>
          <pose>0.2 0 0.335 0 -0 0</pose>
          <geometry>
            <box>
              <size>1.34 1.65746 0.06</size>
            </box>
          </geometry>
          <max_contacts>10</max_contacts>
          <surface>
            <bounce/>
            <friction>
              <ode/>
            </friction>
            <contact>
              <ode/>
            </contact>
          </surface>
        </collision>
        <collision name='cargo_bottom'>
          <pose>-1 0 0.921 0 -0 0</pose>
          <geometry>
            <box>
              <size>1.04609 1.6998 0.01</size>
            </box>
          </geometry>
          <max_contacts>10</max_contacts>
          <surface>
            <bounce/>
            <friction>
              <ode/>
            </friction>
            <contact>
              <ode/>
            </contact>
          </surface>
        </collision>
        <collision name='cargo_front'>
          <pose>-0.495 0 1.06 0 -0 0</pose>
          <geometry>
            <box>
              <size>0.05 1.69982 0.27</size>
            </box>
          </geometry>
          <max_contacts>10</max_contacts>
          <surface>
            <bounce/>
            <friction>
              <ode/>
            </friction>
            <contact>
              <ode/>
            </contact>
          </surface>
        </collision>
        <collision name='cargo_back'>
          <pose>-1.465 0 1.06 0 -0 0</pose>
          <geometry>
            <box>
              <size>0.05 1.69982 0.27</size>
            </box>
          </geometry>
          <max_contacts>10</max_contacts>
          <surface>
            <bounce/>
            <friction>
              <ode/>
            </friction>
            <contact>
              <ode/>
            </contact>
          </surface>
        </collision>
        <collision name='cargo_left'>
          <pose>-0.97 0.82491 1.06 0 -0 0</pose>
          <geometry>
            <box>
              <size>1.04609 0.05 0.27</size>
            </box>
          </geometry>
          <max_contacts>10</max_contacts>
          <surface>
            <bounce/>
            <friction>
              <ode/>
            </friction>
            <contact>
              <ode/>
            </contact>
          </surface>
        </collision>
        <collision name='cargo_right'>
          <pose>-0.97 -0.82491 1.06 0 -0 0</pose>
          <geometry>
            <box>
              <size>1.04609 0.05 0.27</size>
            </box>
          </geometry>
          <max_contacts>10</max_contacts>
          <surface>
            <bounce/>
            <friction>
              <ode/>
            </friction>
            <contact>
              <ode/>
            </contact>
          </surface>
        </collision>
        <collision name='seat'>
          <pose>0 0 0.62 0 -0 0</pose>
          <geometry>
            <box>
              <size>0.52167 1.37206 0.53369</size>
            </box>
          </geometry>
          <surface>
            <contact>
              <ode>
                <min_depth>0.01</min_depth>
              </ode>
            </contact>
            <bounce/>
            <friction>
              <ode/>
            </friction>
          </surface>
          <max_contacts>10</max_contacts>
        </collision>
        <collision name='mud_seat'>
          <pose>0 0 0.86 0 -0 0</pose>
          <geometry>
            <box>
              <size>0.52167 1.3 0.1</size>
            </box>
          </geometry>
          <surface>
            <contact>
              <collide_without_contact>1</collide_without_contact>
              <ode/>
            </contact>
            <bounce/>
            <friction>
              <ode/>
            </friction>
          </surface>
          <max_contacts>10</max_contacts>
        </collision>
        <sensor name='seat_contact' type='contact'>
          <always_on>1</always_on>
          <update_rate>1000</update_rate>
          <contact>
            <collision>mud_seat</collision>
            <topic>__default_topic__</topic>
          </contact>
        </sensor>
        <collision name='seat_back'>
          <pose>-0.26 0 1.125 0 -0.2 0</pose>
          <geometry>
            <box>
              <size>0.06 1.37206 0.6</size>
            </box>
          </geometry>
          <max_contacts>10</max_contacts>
          <surface>
            <bounce/>
            <friction>
              <ode/>
            </friction>
            <contact>
              <ode/>
            </contact>
          </surface>
        </collision>
        <collision name='engine'>
          <pose>1.12 0 0.7 0 -0 0</pose>
          <geometry>
            <box>
              <size>0.58 1.3 0.8</size>
            </box>
          </geometry>
          <max_contacts>10</max_contacts>
          <surface>
            <bounce/>
            <friction>
              <ode/>
            </friction>
            <contact>
              <ode/>
            </contact>
          </surface>
        </collision>
        <collision name='rollcage_top_left'>
          <pose>-0.02 0.76 1.936 3.14159 1.54159 3.14159</pose>
          <geometry>
            <cylinder>
              <radius>0.03</radius>
              <length>0.68</length>
            </cylinder>
          </geometry>
          <max_contacts>10</max_contacts>
          <surface>
            <bounce/>
            <friction>
              <ode/>
            </friction>
            <contact>
              <ode/>
            </contact>
          </surface>
        </collision>
        <collision name='rollcage_top_right'>
          <pose>-0.02 -0.76 1.936 3.14159 1.54159 3.14159</pose>
          <geometry>
            <cylinder>
              <radius>0.03</radius>
              <length>0.68</length>
            </cylinder>
          </geometry>
          <max_contacts>10</max_contacts>
          <surface>
            <bounce/>
            <friction>
              <ode/>
            </friction>
            <contact>
              <ode/>
            </contact>
          </surface>
        </collision>
        <collision name='rollcage_top_front'>
          <pose>0.315 0 1.93 0 -1 0</pose>
          <geometry>
            <box>
              <size>0.01299 1.54 0.10226</size>
            </box>
          </geometry>
          <max_contacts>10</max_contacts>
          <surface>
            <bounce/>
            <friction>
              <ode/>
            </friction>
            <contact>
              <ode/>
            </contact>
          </surface>
        </collision>
        <collision name='rollcage_top_back'>
          <pose>-0.41 0 1.88 0 -0 0</pose>
          <geometry>
            <box>
              <size>0.01299 1.54 0.10226</size>
            </box>
          </geometry>
          <max_contacts>10</max_contacts>
          <surface>
            <bounce/>
            <friction>
              <ode/>
            </friction>
            <contact>
              <ode/>
            </contact>
          </surface>
        </collision>
        <collision name='rollcage_front_left'>
          <pose>0.602 0.755 1.45 0 -0.54 0</pose>
          <geometry>
            <cylinder>
              <radius>0.03</radius>
              <length>1.15</length>
            </cylinder>
          </geometry>
          <max_contacts>10</max_contacts>
          <surface>
            <bounce/>
            <friction>
              <ode/>
            </friction>
            <contact>
              <ode/>
            </contact>
          </surface>
        </collision>
        <collision name='rollcage_front_right'>
          <pose>0.602 -0.755 1.45 0 -0.54 0</pose>
          <geometry>
            <cylinder>
              <radius>0.03</radius>
              <length>1.15</length>
            </cylinder>
          </geometry>
          <max_contacts>10</max_contacts>
          <surface>
            <bounce/>
            <friction>
              <ode/>
            </friction>
            <contact>
              <ode/>
            </contact>
          </surface>
        </collision>
        <collision name='rollcage_back_left'>
          <pose>-0.4 0.755 1.45 0 -0 0</pose>
          <geometry>
            <cylinder>
              <radius>0.03</radius>
              <length>1</length>
            </cylinder>
          </geometry>
          <max_contacts>10</max_contacts>
          <surface>
            <bounce/>
            <friction>
              <ode/>
            </friction>
            <contact>
              <ode/>
            </contact>
          </surface>
        </collision>
        <collision name='rollcage_back_right'>
          <pose>-0.4 -0.755 1.45 0 -0 0</pose>
          <geometry>
            <cylinder>
              <radius>0.03</radius>
              <length>1</length>
            </cylinder>
          </geometry>
          <max_contacts>10</max_contacts>
          <surface>
            <bounce/>
            <friction>
              <ode/>
            </friction>
            <contact>
              <ode/>
            </contact>
          </surface>
        </collision>
        <collision name='rollcage_X_1'>
          <pose>-0.411 0.04 1.445 0.397 -0 0</pose>
          <geometry>
            <box>
              <size>0.01392 1.55724 0.078</size>
            </box>
          </geometry>
          <max_contacts>10</max_contacts>
          <surface>
            <bounce/>
            <friction>
              <ode/>
            </friction>
            <contact>
              <ode/>
            </contact>
          </surface>
        </collision>
        <collision name='rollcage_X_2'>
          <pose>-0.4 -0.04 1.445 -0.397 0 0</pose>
          <geometry>
            <box>
              <size>0.01392 1.55724 0.078</size>
            </box>
          </geometry>
          <max_contacts>10</max_contacts>
          <surface>
            <bounce/>
            <friction>
              <ode/>
            </friction>
            <contact>
              <ode/>
            </contact>
          </surface>
        </collision>
        <collision name='central_hump1_collision'>
          <pose>0.55 -0.1 0.4 0 -0 0</pose>
          <geometry>
            <box>
              <size>0.6 0.15 0.1</size>
            </box>
          </geometry>
          <max_contacts>10</max_contacts>
          <surface>
            <bounce/>
            <friction>
              <ode/>
            </friction>
            <contact>
              <ode/>
            </contact>
          </surface>
        </collision>
        <collision name='central_hump2_collision'>
          <pose>0.7 -0.05 0.45 0 -0.5 0</pose>
          <geometry>
            <box>
              <size>0.2 0.05 0.1</size>
            </box>
          </geometry>
          <max_contacts>10</max_contacts>
          <surface>
            <bounce/>
            <friction>
              <ode/>
            </friction>
            <contact>
              <ode/>
            </contact>
          </surface>
        </collision>
        <collision name='central_hump3_collision'>
          <pose>0.798 -0.125 0.478 0 -0.8 0</pose>
          <geometry>
            <box>
              <size>0.129 0.1 0.05</size>
            </box>
          </geometry>
          <max_contacts>10</max_contacts>
          <surface>
            <bounce/>
            <friction>
              <ode/>
            </friction>
            <contact>
              <ode/>
            </contact>
          </surface>
        </collision>
        <collision name='central_hump4_collision'>
          <pose>0.8135 -0.05 0.45 0 -0 0</pose>
          <geometry>
            <box>
              <size>0.1 0.05 0.1835</size>
            </box>
          </geometry>
          <max_contacts>10</max_contacts>
          <surface>
            <bounce/>
            <friction>
              <ode/>
            </friction>
            <contact>
              <ode/>
            </contact>
          </surface>
        </collision>
        <collision name='central_hump5_collision'>
          <pose>0.84 -0.125 0.45 0 -0 0</pose>
          <geometry>
            <box>
              <size>0.03 0.1 0.1835</size>
            </box>
          </geometry>
          <max_contacts>10</max_contacts>
          <surface>
            <bounce/>
            <friction>
              <ode/>
            </friction>
            <contact>
              <ode/>
            </contact>
          </surface>
        </collision>
        <collision name='central_hump6_collision'>
          <pose>0.82 -0.125 0.475 0 -0 0</pose>
          <geometry>
            <box>
              <size>0.03 0.1 0.05</size>
            </box>
          </geometry>
          <max_contacts>10</max_contacts>
          <surface>
            <bounce/>
            <friction>
              <ode/>
            </friction>
            <contact>
              <ode/>
            </contact>
          </surface>
        </collision>
        <visual name='cargo_visual'>
          <pose>-1 0 1.0323 0 0 -1.5707</pose>
          <geometry>
            <mesh>
              <uri>model://polaris_ranger_xp900/meshes/polaris.dae</uri>
              <submesh>
                <name>Bed</name>
                <center>1</center>
              </submesh>
            </mesh>
          </geometry>
          <material>
            <script>
              <uri>model://polaris_ranger_xp900/materials/scripts</uri>
              <uri>model://polaris_ranger_xp900/materials/textures</uri>
              <name>PolarisXP900/Diffuse</name>
            </script>
          </material>
        </visual>
        <visual name='tailgate_visual'>
          <pose>-1.492 0 1.03 0 0 -1.5707</pose>
          <geometry>
            <mesh>
              <uri>model://polaris_ranger_xp900/meshes/polaris.dae</uri>
              <submesh>
                <name>Tail_Gate</name>
                <center>1</center>
              </submesh>
            </mesh>
          </geometry>
          <material>
            <script>
              <uri>model://polaris_ranger_xp900/materials/scripts</uri>
              <uri>model://polaris_ranger_xp900/materials/textures</uri>
              <name>PolarisXP900/Diffuse</name>
            </script>
          </material>
        </visual>
        <visual name='front_left_brake_visual'>
          <pose>1.12 -0.57488 0.35516 3.1415 -6.77626e-21 1.5707</pose>
          <geometry>
            <mesh>
              <uri>model://polaris_ranger_xp900/meshes/polaris.dae</uri>
              <submesh>
                <name>Brake_Front_Left</name>
                <center>1</center>
              </submesh>
            </mesh>
          </geometry>
          <material>
            <script>
              <uri>model://polaris_ranger_xp900/materials/scripts</uri>
              <uri>model://polaris_ranger_xp900/materials/textures</uri>
              <name>PolarisXP900/Diffuse</name>
            </script>
          </material>
        </visual>
        <visual name='front_right_brake_visual'>
          <pose>1.12 0.57488 0.35516 3.1415 -6.77626e-21 1.5707</pose>
          <geometry>
            <mesh>
              <uri>model://polaris_ranger_xp900/meshes/polaris.dae</uri>
              <submesh>
                <name>Brake_Front_Right</name>
                <center>1</center>
              </submesh>
            </mesh>
          </geometry>
          <material>
            <script>
              <uri>model://polaris_ranger_xp900/materials/scripts</uri>
              <uri>model://polaris_ranger_xp900/materials/textures</uri>
              <name>PolarisXP900/Diffuse</name>
            </script>
          </material>
        </visual>
        <visual name='central_hump1'>
          <pose>0.55 -0.1 0.4 0 -0 0</pose>
          <geometry>
            <box>
              <size>0.6 0.15 0.1</size>
            </box>
          </geometry>
          <material>
            <script>
              <uri>file://media/materials/scripts/gazebo.material</uri>
              <name>Gazebo/DarkGrey</name>
            </script>
          </material>
        </visual>
        <visual name='central_hump2'>
          <pose>0.7 -0.05 0.45 0 -0.5 0</pose>
          <geometry>
            <box>
              <size>0.2 0.05 0.1</size>
            </box>
          </geometry>
          <material>
            <script>
              <uri>file://media/materials/scripts/gazebo.material</uri>
              <name>Gazebo/DarkGrey</name>
            </script>
          </material>
        </visual>
        <visual name='central_hump3'>
          <pose>0.798 -0.125 0.478 0 -0.8 0</pose>
          <geometry>
            <box>
              <size>0.129 0.1 0.05</size>
            </box>
          </geometry>
          <material>
            <script>
              <uri>file://media/materials/scripts/gazebo.material</uri>
              <name>Gazebo/DarkGrey</name>
            </script>
          </material>
        </visual>
        <visual name='central_hump4'>
          <pose>0.8135 -0.05 0.45 0 -0 0</pose>
          <geometry>
            <box>
              <size>0.1 0.05 0.1835</size>
            </box>
          </geometry>
          <material>
            <script>
              <uri>file://media/materials/scripts/gazebo.material</uri>
              <name>Gazebo/DarkGrey</name>
            </script>
          </material>
        </visual>
        <visual name='central_hump5'>
          <pose>0.84 -0.125 0.45 0 -0 0</pose>
          <geometry>
            <box>
              <size>0.03 0.1 0.1835</size>
            </box>
          </geometry>
          <material>
            <script>
              <uri>file://media/materials/scripts/gazebo.material</uri>
              <name>Gazebo/DarkGrey</name>
            </script>
          </material>
        </visual>
        <visual name='central_hump6'>
          <pose>0.82 -0.125 0.475 0 -0 0</pose>
          <geometry>
            <box>
              <size>0.03 0.1 0.05</size>
            </box>
          </geometry>
          <material>
            <script>
              <uri>file://media/materials/scripts/gazebo.material</uri>
              <name>Gazebo/DarkGrey</name>
            </script>
          </material>
        </visual>
        <velocity_decay>
          <linear>0</linear>
          <angular>0</angular>
        </velocity_decay>
        <self_collide>0</self_collide>
        <kinematic>0</kinematic>
        <gravity>1</gravity>
      </link>
      <link name='front_left_wheel'>
        <pose>1.20223 0.71562 0.34697 -1.52 0 0</pose>
        <inertial>
          <mass>12</mass>
          <inertia>
            <ixx>0.5</ixx>
            <ixy>0</ixy>
            <iyy>0.5</iyy>
            <ixz>0</ixz>
            <iyz>0</iyz>
            <izz>1</izz>
          </inertia>
        </inertial>
        <collision name='collision'>
          <geometry>
            <cylinder>
              <radius>0.3175</radius>
              <length>0.2794</length>
            </cylinder>
          </geometry>
          <max_contacts>1</max_contacts>
          <surface>
            <friction>
              <ode>
                <mu>1</mu>
                <mu2>1</mu2>
                <fdir1>0 0 1</fdir1>
                <slip1>0</slip1>
                <slip2>0</slip2>
              </ode>
            </friction>
            <contact>
              <ode>
                <min_depth>0.005</min_depth>
                <kp>1e+08</kp>
              </ode>
            </contact>
            <bounce/>
          </surface>
        </collision>
        <visual name='tire_visual'>
          <pose>0 0 0 -2.65359e-06 1.57079 3.14159</pose>
          <geometry>
            <mesh>
              <uri>model://polaris_ranger_xp900/meshes/polaris.dae</uri>
              <scale>1.0037 0.8862 0.8862</scale>
              <submesh>
                <name>Wheel_Front_Left</name>
                <center>1</center>
              </submesh>
            </mesh>
          </geometry>
          <material>
            <script>
              <uri>model://polaris_ranger_xp900/materials/scripts</uri>
              <uri>model://polaris_ranger_xp900/materials/textures</uri>
              <name>PolarisXP900/Diffuse</name>
            </script>
          </material>
        </visual>
        <velocity_decay>
          <linear>0</linear>
          <angular>0</angular>
        </velocity_decay>
        <self_collide>0</self_collide>
        <kinematic>0</kinematic>
        <gravity>1</gravity>
      </link>
      <link name='front_right_wheel'>
        <pose>1.20223 -0.71562 0.34697 1.52 -0 0</pose>
        <inertial>
          <mass>12</mass>
          <inertia>
            <ixx>0.5</ixx>
            <ixy>0</ixy>
            <iyy>0.5</iyy>
            <ixz>0</ixz>
            <iyz>0</iyz>
            <izz>1</izz>
          </inertia>
        </inertial>
        <collision name='collision'>
          <geometry>
            <cylinder>
              <radius>0.3175</radius>
              <length>0.2794</length>
            </cylinder>
          </geometry>
          <max_contacts>1</max_contacts>
          <surface>
            <friction>
              <ode>
                <mu>1</mu>
                <mu2>1</mu2>
                <fdir1>0 0 1</fdir1>
                <slip1>0</slip1>
                <slip2>0</slip2>
              </ode>
            </friction>
            <contact>
              <ode>
                <min_depth>0.005</min_depth>
                <kp>1e+08</kp>
              </ode>
            </contact>
            <bounce/>
          </surface>
        </collision>
        <visual name='visual'>
          <pose>0 0 0 3.14159 -1.57079 3.14159</pose>
          <geometry>
            <mesh>
              <uri>model://polaris_ranger_xp900/meshes/polaris.dae</uri>
              <scale>1.0037 0.8862 0.8862</scale>
              <submesh>
                <name>Wheel_Front_Right</name>
                <center>1</center>
              </submesh>
            </mesh>
          </geometry>
          <material>
            <script>
              <uri>model://polaris_ranger_xp900/materials/scripts</uri>
              <uri>model://polaris_ranger_xp900/materials/textures</uri>
              <name>PolarisXP900/Diffuse</name>
            </script>
          </material>
        </visual>
        <velocity_decay>
          <linear>0</linear>
          <angular>0</angular>
        </velocity_decay>
        <self_collide>0</self_collide>
        <kinematic>0</kinematic>
        <gravity>1</gravity>
      </link>
      <link name='rear_left_wheel'>
        <pose>-0.99377 0.71562 0.34697 -1.52 0 0</pose>
        <inertial>
          <mass>12</mass>
          <inertia>
            <ixx>0.5</ixx>
            <ixy>0</ixy>
            <iyy>0.5</iyy>
            <ixz>0</ixz>
            <iyz>0</iyz>
            <izz>1</izz>
          </inertia>
        </inertial>
        <collision name='collision'>
          <geometry>
            <cylinder>
              <radius>0.3175</radius>
              <length>0.2794</length>
            </cylinder>
          </geometry>
          <max_contacts>1</max_contacts>
          <surface>
            <friction>
              <ode>
                <mu>1</mu>
                <mu2>1</mu2>
                <fdir1>0 0 1</fdir1>
                <slip1>0</slip1>
                <slip2>0</slip2>
              </ode>
            </friction>
            <contact>
              <ode>
                <min_depth>0.005</min_depth>
                <kp>1e+08</kp>
              </ode>
            </contact>
            <bounce/>
          </surface>
        </collision>
        <visual name='visual'>
          <pose>0 0 0 3.14159 -1.57079 3.14159</pose>
          <geometry>
            <mesh>
              <uri>model://polaris_ranger_xp900/meshes/polaris.dae</uri>
              <scale>1.0037 0.8862 0.8862</scale>
              <submesh>
                <name>Wheels_Rear_Left</name>
                <center>1</center>
              </submesh>
            </mesh>
          </geometry>
          <material>
            <script>
              <uri>model://polaris_ranger_xp900/materials/scripts</uri>
              <uri>model://polaris_ranger_xp900/materials/textures</uri>
              <name>PolarisXP900/Diffuse</name>
            </script>
          </material>
        </visual>
        <velocity_decay>
          <linear>0</linear>
          <angular>0</angular>
        </velocity_decay>
        <self_collide>0</self_collide>
        <kinematic>0</kinematic>
        <gravity>1</gravity>
      </link>
      <link name='rear_right_wheel'>
        <pose>-0.99377 -0.71562 0.34697 1.52 -0 0</pose>
        <inertial>
          <mass>12</mass>
          <inertia>
            <ixx>0.5</ixx>
            <ixy>0</ixy>
            <iyy>0.5</iyy>
            <ixz>0</ixz>
            <iyz>0</iyz>
            <izz>1</izz>
          </inertia>
        </inertial>
        <collision name='collision'>
          <geometry>
            <cylinder>
              <radius>0.3175</radius>
              <length>0.2794</length>
            </cylinder>
          </geometry>
          <max_contacts>1</max_contacts>
          <surface>
            <friction>
              <ode>
                <mu>1</mu>
                <mu2>1</mu2>
                <fdir1>0 0 1</fdir1>
                <slip1>0</slip1>
                <slip2>0</slip2>
              </ode>
            </friction>
            <contact>
              <ode>
                <min_depth>0.005</min_depth>
                <kp>1e+08</kp>
              </ode>
            </contact>
            <bounce/>
          </surface>
        </collision>
        <visual name='visual'>
          <pose>0 0 0 3.14159 -1.57079 3.14159</pose>
          <geometry>
            <mesh>
              <uri>model://polaris_ranger_xp900/meshes/polaris.dae</uri>
              <scale>1.0037 0.8862 0.8862</scale>
              <submesh>
                <name>Wheels_Rear_Right</name>
                <center>1</center>
              </submesh>
            </mesh>
          </geometry>
          <material>
            <script>
              <uri>model://polaris_ranger_xp900/materials/scripts</uri>
              <uri>model://polaris_ranger_xp900/materials/textures</uri>
              <name>PolarisXP900/Diffuse</name>
            </script>
          </material>
        </visual>
        <velocity_decay>
          <linear>0</linear>
          <angular>0</angular>
        </velocity_decay>
        <self_collide>0</self_collide>
        <kinematic>0</kinematic>
        <gravity>1</gravity>
      </link>
      <link name='gas_pedal'>
        <pose>0.63 0.1 0.58 0 -0 0</pose>
        <gravity>0</gravity>
        <inertial>
          <mass>0.1</mass>
          <pose>0 0 0 0 -0 0</pose>
          <inertia>
            <ixx>0.01</ixx>
            <ixy>0</ixy>
            <ixz>0</ixz>
            <iyy>0.01</iyy>
            <iyz>0</iyz>
            <izz>0.01</izz>
          </inertia>
        </inertial>
        <collision name='gas_pedal_collision'>
          <pose>-0.0385 0 -0.086 3.14159 1.12559 3.14159</pose>
          <geometry>
            <box>
              <size>0.1069 0.077 0.01</size>
            </box>
          </geometry>
          <max_contacts>10</max_contacts>
          <surface>
            <bounce/>
            <friction>
              <ode/>
            </friction>
            <contact>
              <ode/>
            </contact>
          </surface>
        </collision>
        <visual name='visual'>
          <pose>0 0 0 0 0 -1.5707</pose>
          <geometry>
            <mesh>
              <uri>model://polaris_ranger_xp900/meshes/polaris.dae</uri>
              <submesh>
                <name>Gas_Pedal</name>
                <center>1</center>
              </submesh>
            </mesh>
          </geometry>
          <material>
            <script>
              <uri>model://polaris_ranger_xp900/materials/scripts</uri>
              <uri>model://polaris_ranger_xp900/materials/textures</uri>
              <name>PolarisXP900/Diffuse</name>
            </script>
          </material>
        </visual>
        <velocity_decay>
          <linear>0</linear>
          <angular>0</angular>
        </velocity_decay>
        <self_collide>0</self_collide>
        <kinematic>0</kinematic>
      </link>
      <link name='brake_pedal'>
        <gravity>0</gravity>
        <pose>0.64 0.27 0.58 0 -0 0</pose>
        <inertial>
          <mass>0.1</mass>
          <pose>0 0 0 0 -0 0</pose>
          <inertia>
            <ixx>0.01</ixx>
            <ixy>0</ixy>
            <ixz>0</ixz>
            <iyy>0.01</iyy>
            <iyz>0</iyz>
            <izz>0.01</izz>
          </inertia>
        </inertial>
        <collision name='brake_pedal_collision'>
          <pose>-0.04 0 -0.086 3.14159 1.14259 3.14159</pose>
          <geometry>
            <box>
              <size>0.063 0.08 0.01</size>
            </box>
          </geometry>
          <max_contacts>10</max_contacts>
          <surface>
            <bounce/>
            <friction>
              <ode/>
            </friction>
            <contact>
              <ode/>
            </contact>
          </surface>
        </collision>
        <visual name='visual'>
          <pose>0 0 0 0 0 -1.5707</pose>
          <geometry>
            <mesh>
              <uri>model://polaris_ranger_xp900/meshes/polaris.dae</uri>
              <submesh>
                <name>Brake_Pedal</name>
                <center>1</center>
              </submesh>
            </mesh>
          </geometry>
          <material>
            <script>
              <uri>model://polaris_ranger_xp900/materials/scripts</uri>
              <uri>model://polaris_ranger_xp900/materials/textures</uri>
              <name>PolarisXP900/Diffuse</name>
            </script>
          </material>
        </visual>
        <velocity_decay>
          <linear>0</linear>
          <angular>0</angular>
        </velocity_decay>
        <self_collide>0</self_collide>
        <kinematic>0</kinematic>
      </link>
      <link name='front_right_wheel_steering_block'>
        <pose>1.20223 -0.5 0.35515 1.5708 -0 0</pose>
        <inertial>
          <mass>1</mass>
          <inertia>
            <ixx>1</ixx>
            <ixy>0</ixy>
            <iyy>1</iyy>
            <ixz>0</ixz>
            <iyz>0</iyz>
            <izz>1</izz>
          </inertia>
        </inertial>
        <collision name='collision'>
          <geometry>
            <cylinder>
              <radius>0.05</radius>
              <length>0.01</length>
            </cylinder>
          </geometry>
          <max_contacts>10</max_contacts>
          <surface>
            <bounce/>
            <friction>
              <ode/>
            </friction>
            <contact>
              <ode/>
            </contact>
          </surface>
        </collision>
        <velocity_decay>
          <linear>0</linear>
          <angular>0</angular>
        </velocity_decay>
        <self_collide>0</self_collide>
        <kinematic>0</kinematic>
        <gravity>1</gravity>
      </link>
      <link name='front_left_wheel_steering_block'>
        <pose>1.20223 0.5 0.35515 1.5708 -0 0</pose>
        <inertial>
          <mass>1</mass>
          <inertia>
            <ixx>1</ixx>
            <ixy>0</ixy>
            <iyy>1</iyy>
            <ixz>0</ixz>
            <iyz>0</iyz>
            <izz>1</izz>
          </inertia>
        </inertial>
        <collision name='collision'>
          <geometry>
            <cylinder>
              <radius>0.05</radius>
              <length>0.01</length>
            </cylinder>
          </geometry>
          <max_contacts>10</max_contacts>
          <surface>
            <bounce/>
            <friction>
              <ode/>
            </friction>
            <contact>
              <ode/>
            </contact>
          </surface>
        </collision>
        <velocity_decay>
          <linear>0</linear>
          <angular>0</angular>
        </velocity_decay>
        <self_collide>0</self_collide>
        <kinematic>0</kinematic>
        <gravity>1</gravity>
      </link>
      <link name='steering_wheel'>
        <pose>0.42 0.46 1.2 0 -0.87 0</pose>
        <inertial>
          <mass>1</mass>
          <pose>-0.002 0 0 0 -0 0</pose>
          <inertia>
            <ixx>0.012</ixx>
            <ixy>0</ixy>
            <ixz>0</ixz>
            <iyy>0.012</iyy>
            <iyz>0</iyz>
            <izz>0.024</izz>
          </inertia>
        </inertial>
        <collision name='collision'>
          <pose>-0.03 0 -0.120825 -0.6108 -5.55112e-17 -1.5708</pose>
          <geometry>
            <mesh>
              <uri>model://polaris_ranger_xp900/meshes/polaris.dae</uri>
              <submesh>
                <name>Steering_Wheel</name>
                <center>1</center>
              </submesh>
            </mesh>
          </geometry>
          <surface>
            <contact>
              <ode>
                <min_depth>0.003</min_depth>
              </ode>
            </contact>
            <bounce/>
            <friction>
              <ode/>
            </friction>
          </surface>
          <max_contacts>10</max_contacts>
        </collision>
        <visual name='visual'>
          <pose>-0.03 0 -0.120825 -0.6108 -5.55112e-17 -1.5708</pose>
          <geometry>
            <mesh>
              <uri>model://polaris_ranger_xp900/meshes/polaris.dae</uri>
              <submesh>
                <name>Steering_Wheel</name>
                <center>1</center>
              </submesh>
            </mesh>
          </geometry>
          <material>
            <script>
              <uri>model://polaris_ranger_xp900/materials/scripts</uri>
              <uri>model://polaris_ranger_xp900/materials/textures</uri>
              <name>PolarisXP900/Diffuse</name>
            </script>
          </material>
        </visual>
        <velocity_decay>
          <linear>0</linear>
          <angular>0</angular>
        </velocity_decay>
        <self_collide>0</self_collide>
        <kinematic>0</kinematic>
        <gravity>1</gravity>
      </link>
      <link name='hand_brake'>
        <pose>0.53 0.205 1.05 0 -0 0</pose>
        <inertial>
          <mass>0.5</mass>
          <inertia>
            <ixx>0.1</ixx>
            <ixy>0</ixy>
            <ixz>0</ixz>
            <iyy>0.1</iyy>
            <iyz>0</iyz>
            <izz>0.05</izz>
          </inertia>
        </inertial>
        <collision name='hand_brake_collision'>
          <pose>0 0 0.05 -0.2 -1.38778e-17 -1.5708</pose>
          <geometry>
            <mesh>
              <uri>model://polaris_ranger_xp900/meshes/polaris.dae</uri>
              <submesh>
                <name>Shifter</name>
                <center>1</center>
              </submesh>
            </mesh>
          </geometry>
          <max_contacts>10</max_contacts>
          <surface>
            <bounce/>
            <friction>
              <ode/>
            </friction>
            <contact>
              <ode/>
            </contact>
          </surface>
        </collision>
        <visual name='hand_brake_visual'>
          <pose>0 0 0.05 -0.2 -1.38778e-17 -1.5708</pose>
          <geometry>
            <mesh>
              <uri>model://polaris_ranger_xp900/meshes/polaris.dae</uri>
              <submesh>
                <name>Shifter</name>
                <center>1</center>
              </submesh>
            </mesh>
          </geometry>
          <material>
            <script>
              <uri>model://polaris_ranger_xp900/materials/scripts</uri>
              <uri>model://polaris_ranger_xp900/materials/textures</uri>
              <name>PolarisXP900/Diffuse</name>
            </script>
          </material>
        </visual>
        <velocity_decay>
          <linear>0</linear>
          <angular>0</angular>
        </velocity_decay>
        <self_collide>0</self_collide>
        <kinematic>0</kinematic>
        <gravity>1</gravity>
      </link>
      <link name='FNR_switch'>
        <pose>0.54 0.1 1.15 0 0.25 0</pose>
        <inertial>
          <mass>0.1</mass>
          <inertia>
            <ixx>0.1</ixx>
            <ixy>0</ixy>
            <ixz>0</ixz>
            <iyy>6e-05</iyy>
            <iyz>0</iyz>
            <izz>0.1</izz>
          </inertia>
        </inertial>
        <collision name='FNR_switch'>
          <geometry>
            <box>
              <size>0.02 0.04 0.08</size>
            </box>
          </geometry>
          <max_contacts>10</max_contacts>
          <surface>
            <bounce/>
            <friction>
              <ode/>
            </friction>
            <contact>
              <ode/>
            </contact>
          </surface>
        </collision>
        <visual name='FNR_switch_F'>
          <transparency>0</transparency>
          <geometry>
            <box>
              <size>0.02 0.04 0.08</size>
            </box>
          </geometry>
          <material>
            <script>
              <uri>model://polaris_ranger_ev/materials/scripts</uri>
              <uri>model://polaris_ranger_ev/materials/textures</uri>
              <name>FNR_switch_F</name>
            </script>
          </material>
        </visual>
        <visual name='FNR_switch_R'>
          <transparency>1</transparency>
          <geometry>
            <box>
              <size>0.0199 0.0399 0.0799</size>
            </box>
          </geometry>
          <material>
            <script>
              <uri>model://polaris_ranger_ev/materials/scripts</uri>
              <uri>model://polaris_ranger_ev/materials/textures</uri>
              <name>FNR_switch_R</name>
            </script>
          </material>
        </visual>
        <velocity_decay>
          <linear>0</linear>
          <angular>0</angular>
        </velocity_decay>
        <self_collide>0</self_collide>
        <kinematic>0</kinematic>
        <gravity>1</gravity>
      </link>
      <joint name='front_left_steering_joint' type='revolute'>
        <child>front_left_wheel_steering_block</child>
        <parent>chassis</parent>
        <axis>
          <xyz>0 0 1</xyz>
          <limit>
            <lower>-0.7727</lower>
            <upper>0.7727</upper>
          </limit>
          <dynamics>
            <damping>50</damping>
          </dynamics>
        </axis>
        <physics>
          <ode>
            <cfm_damping>1</cfm_damping>
            <limit>
              <cfm>0</cfm>
              <erp>0.9</erp>
            </limit>
          </ode>
        </physics>
      </joint>
      <joint name='front_left_wheel_joint' type='revolute'>
        <child>front_left_wheel</child>
        <parent>front_left_wheel_steering_block</parent>
        <axis>
          <xyz>0 1 0.05</xyz>
          <limit>
            <lower>-1e+16</lower>
            <upper>1e+16</upper>
          </limit>
        </axis>
      </joint>
      <joint name='front_right_steering_joint' type='revolute'>
        <child>front_right_wheel_steering_block</child>
        <parent>chassis</parent>
        <axis>
          <xyz>0 0 1</xyz>
          <limit>
            <lower>-0.7727</lower>
            <upper>0.7727</upper>
          </limit>
          <dynamics>
            <damping>50</damping>
          </dynamics>
        </axis>
        <physics>
          <ode>
            <cfm_damping>1</cfm_damping>
            <limit>
              <cfm>0</cfm>
              <erp>0.9</erp>
            </limit>
          </ode>
        </physics>
      </joint>
      <joint name='front_right_wheel_joint' type='revolute'>
        <child>front_right_wheel</child>
        <parent>front_right_wheel_steering_block</parent>
        <axis>
          <xyz>0 1 -0.05</xyz>
          <limit>
            <lower>-1e+16</lower>
            <upper>1e+16</upper>
          </limit>
        </axis>
      </joint>
      <joint name='rear_left_wheel_joint' type='revolute'>
        <child>rear_left_wheel</child>
        <parent>chassis</parent>
        <axis>
          <xyz>0 1 0.05</xyz>
          <limit>
            <lower>-1e+16</lower>
            <upper>1e+16</upper>
          </limit>
        </axis>
      </joint>
      <joint name='rear_right_wheel_joint' type='revolute'>
        <pose>0 0 -0.1 0 -0 0</pose>
        <child>rear_right_wheel</child>
        <parent>chassis</parent>
        <axis>
          <xyz>0 1 -0.05</xyz>
          <limit>
            <lower>-1e+16</lower>
            <upper>1e+16</upper>
          </limit>
        </axis>
      </joint>
      <joint name='rear_differential_joint' type='revolute'>
        <child>rear_right_wheel</child>
        <parent>rear_left_wheel</parent>
        <axis>
          <xyz>0 1 0</xyz>
          <dynamics>
            <damping>70</damping>
          </dynamics>
          <limit>
            <lower>-1e+16</lower>
            <upper>1e+16</upper>
          </limit>
        </axis>
        <physics>
          <ode>
            <erp>0</erp>
            <cfm>1000</cfm>
            <cfm_damping>1</cfm_damping>
            <limit>
              <cfm>0</cfm>
              <erp>0.2</erp>
            </limit>
          </ode>
        </physics>
      </joint>
      <joint name='gas_joint' type='prismatic'>
        <parent>chassis</parent>
        <child>gas_pedal</child>
        <axis>
          <xyz>1 0 -1</xyz>
          <limit>
            <lower>0</lower>
            <upper>0.08</upper>
          </limit>
          <dynamics>
            <damping>3</damping>
          </dynamics>
        </axis>
        <physics>
          <ode>
            <cfm_damping>1</cfm_damping>
            <limit>
              <cfm>0</cfm>
              <erp>0.2</erp>
            </limit>
          </ode>
        </physics>
      </joint>
      <joint name='brake_joint' type='prismatic'>
        <parent>chassis</parent>
        <child>brake_pedal</child>
        <axis>
          <xyz>1 0 -0.6</xyz>
          <limit>
            <lower>0</lower>
            <upper>0.08</upper>
          </limit>
          <dynamics>
            <damping>3</damping>
          </dynamics>
        </axis>
        <physics>
          <ode>
            <cfm_damping>1</cfm_damping>
            <limit>
              <cfm>0</cfm>
              <erp>0.2</erp>
            </limit>
          </ode>
        </physics>
      </joint>
      <joint name='steering_joint' type='revolute'>
        <pose>0 0 0 0 -0 0</pose>
        <parent>chassis</parent>
        <child>steering_wheel</child>
        <axis>
          <xyz>-1 0 0.84365</xyz>
          <limit>
            <lower>-3.14</lower>
            <upper>3.14</upper>
          </limit>
          <dynamics>
            <damping>1</damping>
          </dynamics>
        </axis>
        <physics>
          <ode>
            <cfm_damping>1</cfm_damping>
            <limit>
              <cfm>0</cfm>
              <erp>0.2</erp>
            </limit>
          </ode>
        </physics>
      </joint>
      <joint name='hand_brake_joint' type='revolute'>
        <parent>chassis</parent>
        <child>hand_brake</child>
        <axis>
          <xyz>0 -1 0</xyz>
          <limit>
            <lower>0</lower>
            <upper>0.6</upper>
          </limit>
          <dynamics>
            <damping>1</damping>
          </dynamics>
        </axis>
        <physics>
          <ode>
            <cfm_damping>1</cfm_damping>
            <limit>
              <cfm>0</cfm>
              <erp>0.2</erp>
            </limit>
          </ode>
        </physics>
      </joint>
      <joint name='FNR_switch_joint' type='revolute'>
        <parent>chassis</parent>
        <child>FNR_switch</child>
        <axis>
          <xyz>0 -1 0</xyz>
          <limit>
            <lower>-0.3</lower>
            <upper>0.3</upper>
          </limit>
          <dynamics>
            <damping>0.01</damping>
          </dynamics>
        </axis>
        <physics>
          <ode>
            <cfm_damping>1</cfm_damping>
            <limit>
              <cfm>0</cfm>
              <erp>0.2</erp>
            </limit>
          </ode>
        </physics>
      </joint>
      <pose>-1.48561 -5 0 0 -0 0</pose>
      <plugin name='differential_drive_controller' filename='libgazebo_ros_diff_drive.so'>
        <alwaysOn>true</alwaysOn>
        <updateRate>100</updateRate>
        <leftJoint>left_wheel_hinge</leftJoint>
        <rightJoint>right_wheel_hinge</rightJoint>
        <wheelSeparation>0.39</wheelSeparation>
        <wheelDiameter>0.15</wheelDiameter>
        <torque>5</torque>
        <commandTopic>cmd_vel</commandTopic>
        <odometryTopic>odom</odometryTopic>
        <odometryFrame>odom</odometryFrame>
        <robotBaseFrame>chassis</robotBaseFrame>
      </plugin>
      <pose>0 0 0 0 -0 0</pose>
      <static>0</static>
    </model>
    <state world_name='default'>
      <sim_time>49 149000000</sim_time>
      <real_time>114 834201314</real_time>
      <wall_time>1466225192 360718381</wall_time>
      <model name='ground_plane'>
        <pose>1 -1.55027 0 0 -0 0</pose>
        <link name='link'>
          <pose>1 -1.55027 0 0 -0 0</pose>
          <velocity>0 0 0 0 -0 0</velocity>
          <acceleration>0 0 0 0 -0 0</acceleration>
          <wrench>0 0 0 0 -0 0</wrench>
        </link>
      </model>
      <model name='hku_m100'>
        <pose>-1004.95 376.806 0.113361 -8e-06 -6.4e-05 0.256099</pose>
        <link name='base_link'>
          <pose>-1004.95 376.806 0.113361 -8e-06 -6.4e-05 0.256099</pose>
          <velocity>-0.005516 -0.004049 -0.012498 0.022659 -0.07096 0.007191</velocity>
          <acceleration>-5.98933 -2.20658 -3.46048 0.400232 -0.657091 0.051046</acceleration>
          <wrench>-8.84624 -3.25912 -5.11113 0 -0 0</wrench>
        </link>
        <link name='camera_link'>
          <pose>-1004.85 376.831 0.073369 0.584615 -7.6e-05 0.256089</pose>
          <velocity>-0.001865 -0.001737 -0.004159 0.423423 0.640772 0.012129</velocity>
          <acceleration>-1.56124 0.886256 6.9607 -0.446819 0.867717 -2.57547</acceleration>
          <wrench>-0.001561 0.000886 0.006961 0 -0 0</wrench>
        </link>
      </model>
      <model name='polaris_ranger_xp900'>
        <pose>-1.58547 -5.00001 -0.027977 -5e-06 0.000135 2.1e-05</pose>
        <link name='FNR_switch'>
          <pose>-1.04532 -4.89999 1.12195 -5e-06 0.204711 2e-05</pose>
          <velocity>-0.013633 -6.2e-05 -0.001352 8.6e-05 -0.002719 -9e-06</velocity>
          <acceleration>-0.000235 -8e-06 1.8e-05 1.1e-05 -0 0</acceleration>
          <wrench>-2.4e-05 -1e-06 2e-06 0 -0 0</wrench>
        </link>
        <link name='brake_pedal'>
          <pose>-0.928721 -4.72999 0.541922 -7e-06 0.00014 2.2e-05</pose>
          <velocity>-0.01183 -9e-06 -0.001093 0.000141 -0.002892 -4.1e-05</velocity>
          <acceleration>-0.000232 -2e-06 2.5e-05 1e-06 -1e-06 0</acceleration>
          <wrench>-2.3e-05 -0 2e-06 0 -0 0</wrench>
        </link>
        <link name='chassis'>
          <pose>-1.58547 -5.00001 -0.027977 -5e-06 0.000135 2.1e-05</pose>
          <velocity>-0.010397 4.2e-05 -0.002942 8.4e-05 -0.002844 -1e-05</velocity>
          <acceleration>-0.000226 0 1.2e-05 2e-06 -1e-05 0</acceleration>
          <wrench>-0.162656 0.000137 0.008602 0 -0 0</wrench>
        </link>
        <link name='front_left_wheel'>
          <pose>-0.385029 -4.28439 0.319148 -1.51751 -0.316261 -0.00788</pose>
          <velocity>-0.011612 -2.2e-05 -0.004511 0.001081 -0.036208 -0.00102</velocity>
          <acceleration>-0.000233 -1e-06 0.000165 2e-06 -3e-05 -2e-06</acceleration>
          <wrench>-0.002796 -1.8e-05 0.001978 0 -0 0</wrench>
        </link>
        <link name='front_left_wheel_steering_block'>
          <pose>-0.383205 -4.5 0.327404 1.57083 0.000135 0.008452</pose>
          <velocity>-0.011498 -8.2e-05 -0.005717 -0.000547 -0.002859 0.000692</velocity>
          <acceleration>-0.000226 1e-06 0.000193 2.6e-05 -1.4e-05 3.5e-05</acceleration>
          <wrench>-0.000226 1e-06 0.000193 0 -0 0</wrench>
        </link>
        <link name='front_right_wheel'>
          <pose>-0.385125 -5.71557 0.31915 1.5175 -0.316359 0.007348</pose>
          <velocity>-0.011614 -5e-06 -0.004379 -0.000975 -0.03621 0.00101</velocity>
          <acceleration>-0.000233 -1e-06 0.000187 -1e-06 -3e-05 2e-06</acceleration>
          <wrench>-0.002791 -1.7e-05 0.002243 0 -0 0</wrench>
        </link>
        <link name='front_right_wheel_steering_block'>
          <pose>-0.383185 -5.49996 0.327402 1.57076 0.000136 -0.008992</pose>
          <velocity>-0.011497 5.9e-05 -0.005483 0.000706 -0.002875 -0.000698</velocity>
          <acceleration>-0.000226 -4e-06 0.000229 -1.1e-05 -1.3e-05 -3.2e-05</acceleration>
          <wrench>-0.000226 -4e-06 0.000229 0 -0 0</wrench>
        </link>
        <link name='gas_pedal'>
          <pose>-0.932893 -4.89999 0.529425 -5e-06 0.000138 2.1e-05</pose>
          <velocity>-0.011774 -1e-05 -0.001225 0.000101 -0.002858 -2.4e-05</velocity>
          <acceleration>-0.00023 -2e-06 2.4e-05 1e-06 -1e-06 0</acceleration>
          <wrench>-2.3e-05 -0 2e-06 0 -0 0</wrench>
        </link>
        <link name='hand_brake'>
          <pose>-1.05534 -4.79499 1.02195 -5e-06 -0.056626 2.1e-05</pose>
          <velocity>-0.013352 -5.3e-05 -0.001371 8.6e-05 -0.002717 -9e-06</velocity>
          <acceleration>-0.000234 -7e-06 1.9e-05 2e-06 -3e-06 0</acceleration>
          <wrench>-0.000117 -3e-06 1e-05 0 -0 0</wrench>
        </link>
        <link name='rear_left_wheel'>
          <pose>-2.57921 -4.28441 0.319146 -1.51748 -0.31383 -0.016198</pose>
          <velocity>-0.011402 -0.000165 -0.006975 0.001655 -0.035809 -0.001671</velocity>
          <acceleration>-0.000225 1e-06 1.1e-05 1.29247e-26 -2.9e-05 -4e-06</acceleration>
          <wrench>-0.0027 6e-06 0.000137 0 -0 0</wrench>
        </link>
        <link name='rear_right_wheel'>
          <pose>-2.57921 -5.71565 0.319146 1.51749 -0.313831 0.016238</pose>
          <velocity>-0.011422 0.000266 -0.006951 -0.001983 -0.035864 0.001655</velocity>
          <acceleration>-0.000226 -0 -1.2e-05 0 -3e-05 4e-06</acceleration>
          <wrench>-0.002707 -1e-06 -0.000145 0 -0 0</wrench>
        </link>
        <link name='steering_wheel'>
          <pose>-1.16532 -4.53999 1.17196 0.000589 -0.869864 -0.000754</pose>
          <velocity>-0.01377 -6.5e-05 -0.001656 7.4e-05 -0.0028 2e-06</velocity>
          <acceleration>-0.000236 -8e-06 2e-05 0 -0 0</acceleration>
          <wrench>-0.000236 -8e-06 2e-05 0 -0 0</wrench>
        </link>
      </model>
      <model name='unit_box_yellow'>
        <pose>3 2 0.261841 1e-06 -1e-06 0</pose>
        <link name='link'>
          <pose>3 2 0.261841 1e-06 -1e-06 0</pose>
          <velocity>-0 -0 0.01 0 -0 0</velocity>
          <acceleration>0 0 0 0 -0 0</acceleration>
          <wrench>0 0 0 0 -0 0</wrench>
        </link>
      </model>
    </state>
    <gui fullscreen='0'>
      <camera name='user_camera'>
        <pose>-8.8064 -1.05978 10.1097 0 0.887642 -0.162994</pose>
        <view_controller>orbit</view_controller>
      </camera>
    </gui>
  </world>
</sdf>
